import Review from "../models/reviewModel";
import { catchAsync } from "../utils/catchAsync";
import AppError from "../utils/appError";

export const createReview = catchAsync(async (req, res, next) => {
  const newReview = await Review.create({
    user: req.user.id,
    ...req.body,
  });

  res.status(201).json({
    status: "success",
    data: {
      review: newReview,
    },
  });
});

export const getAllReviews = catchAsync(async (req, res, next) => {
  const reviews = await Review.find();

  res.status(200).json({
    status: "success",
    results: reviews.length,
    data: {
      reviews,
    },
  });
});

export const getReview = catchAsync(async (req, res, next) => {
  const review = await Review.findById(req.params.id);

  if (!review) {
    return next(new AppError("No review found with that ID", 404));
  }

  res.status(200).json({
    status: "success",
    data: {
      review,
    },
  });
});

export const updateReview = catchAsync(async (req, res, next) => {
  const review = await Review.findByIdAndUpdate(req.params.id, req.body, {
    new: true,
    runValidators: true,
  });

  if (!review) {
    return next(new AppError("No review found with that ID", 404));
  }

  res.status(200).json({
    status: "success",
    data: {
      review,
    },
  });
});

export const deleteReview = catchAsync(async (req, res, next) => {
  const review = await Review.findByIdAndDelete(req.params.id);

  if (!review) {
    return next(new AppError("No review found with that ID", 404));
  }

  res.status(204).json({
    status: "success",
    data: null,
  });
});
